Workbook

Sheet Read me
A1: CTC Build House costing — how to use
A3: 1. Assumptions: FX, Kahn trade discount, tariff, labour rates, margins, HH fee. Yellow = placeholder, needs a real number.
A4: 2. Categories: one row per part type, derived from Chelsea's own Shopify tags. Set install hours, paint hours, freight and duty once per category; every item inherits it.
A5: 3. Catalog: all 212 active CTC options, costed. Parts sell at Kahn retail (USD) plus freight, duty, tariff and fees; our parts margin is the 25% trade discount. Change an item's Category dropdown to re-cost it. "Total price" is what the quote line should be; "System price today" is what the platform charges now (web price × fx × markup).
A6: 4. Quote Calculator: pick SKUs, set quantities, read the total and margin.
A8: Origins: tariff is driven by country of origin (Origins sheet). Wheels = Taiwan (15% reciprocal + Section 232 aluminium on the metal content). Other parts default UK (10%); override to China per item in Catalog column X.
A9: Confirm HTS codes and the 232 aluminium treatment with the broker before the first shipment — the wheel number moves a lot on that.
A10: Once the category numbers settle, they move into the system as per-group cost fields so quotes price themselves.
A11: Source data: docs/exports/ctc-catalog.csv (PR #7, commit bfddd74), live Shopify prices on 2026-10-23.

Sheet Assumptions
A1: CTC Build House — costing assumptions
A2: Blue cells are inputs. Yellow cells are placeholders that need a real number. Everything else is calculated.
A4: Assumption | B4: Value | C4: Notes
A5: GBP → USD rate | B5: 1.27 | C5: Matches builder_terms.fx_rate in the system. Update both together.
A6: Kahn trade discount off web price | B6: 0.25 | C6: Agreed with Afzal: 25% off web price. Web GBP × 0.75 = kit cost to us.
A7: Merchandise processing fee | B7: 0.003464 | C7: CBP MPF, 0.3464% of value; min $32.71, max $634.62 per entry (FY2025). Modelled flat % here.
A8: Customs brokerage per shipment | B8: 150 | C8: Per entry. Spread over items by setting shipments per month below.
A9: Items per consolidated shipment | B9: 6 | C9: Used to spread brokerage across items.
A10: Shop labour rate ($/hr, billed) | B10: 200 | C10: Billed install rate, $200 across the board. Partner-shop cost sits under this.
A11: Paint labour rate ($/hr, billed) | B11: 200 | C11: Billed paint and prep rate, $200 across the board.
A12: Partner shop cost rate ($/hr) | B12: 110 | C12: PLACEHOLDER — what the paint/fit shop actually charges us per hour. The spread to the billed rate is our labour margin.
A13: Humble House fee (% of sale price) | B13: 0.05 | C13: Flat 5% of the customer sale price, absorbed by Build House (not added to the quote). Clean to track from the invoice total.
A14: Chelsea Conversion base (per job) | B14: 1500 | C14: PLACEHOLDER — the flat per-job charge behind the "Chelsea Conversion" tier in the system (currently $0 there): vehicle intake, inspection, PDI, detail, handover, admin. Set to 0 if you would rather bury it in labour.

Sheet Origins
A1: Country of origin | B1: Additional tariff % | C1: Section 232 aluminium (wheels) % | D1: Notes
A2: United Kingdom | B2: 0.1 | C2: 0 | D2: US–UK Economic Prosperity Deal: UK auto parts at 10% (Section 232 relief). Verify per HTS.
A3: Taiwan | B3: 0.15 | C3: 0.5 | D3: US–Taiwan Agreement on Reciprocal Trade (Feb 2026): reciprocal tariff capped at 15%. Aluminium wheels (8708.70) are on the Section 232 aluminium-derivative list at 50% on the aluminium content value; Administration was reviewing the list in Feb 2026 — confirm with broker.
A4: China | B4: 0.45 | C4: 0.5 | D4: PLACEHOLDER — reciprocal 10% + IEEPA 10% + Section 301 25% on auto parts ≈ 45%; 232 aluminium 50% on wheels. Verify per HTS.
A7: Aluminium share of a wheel's value (for Section 232) | B7: 0.4 | D7: PLACEHOLDER — 232 derivative duty applies to the aluminium content, not the whole wheel. Kahn's customs invoice states it.

Sheet Categories
A1: Category | B1: Install hours | C1: Paint hours | D1: Paint materials ($) | E1: Freight per item ($) | F1: HTS duty % | G1: Country of origin | H1: Items in catalog | I1: Notes
A2: Body kit | B2: 24 | C2: 16 | D2: 1500 | E2: 1200 | F2: 0.025 | G2: United Kingdom | H2: =COUNTIF(Catalog!$C:$C,A2) -> 11 | I2: Rough estimate — adjust from first real job. Install = fit only; Paint = prep + spray.
A3: Wheel arches | B3: 10 | C3: 6 | D3: 600 | E3: 500 | F3: 0.025 | G3: United Kingdom | H3: =COUNTIF(Catalog!$C:$C,A3) -> 2 | I3: Rough estimate — adjust from first real job. Install = fit only; Paint = prep + spray.
A4: Roof conversion | B4: 16 | C4: 4 | D4: 300 | E4: 600 | F4: 0.025 | G4: United Kingdom | H4: =COUNTIF(Catalog!$C:$C,A4) -> 1 | I4: Rough estimate — adjust from first real job. Install = fit only; Paint = prep + spray.
A5: Front bumper | B5: 4 | C5: 3 | D5: 250 | E5: 300 | F5: 0.025 | G5: United Kingdom | H5: =COUNTIF(Catalog!$C:$C,A5) -> 6 | I5: Rough estimate — adjust from first real job. Install = fit only; Paint = prep + spray.
A6: Grille | B6: 2 | C6: 1 | D6: 80 | E6: 120 | F6: 0.025 | G6: United Kingdom | H6: =COUNTIF(Catalog!$C:$C,A6) -> 9 | I6: Rough estimate — adjust from first real job. Install = fit only; Paint = prep + spray.
A7: Bonnet | B7: 4 | C7: 4 | D7: 350 | E7: 400 | F7: 0.025 | G7: United Kingdom | H7: =COUNTIF(Catalog!$C:$C,A7) -> 2 | I7: Rough estimate — adjust from first real job. Install = fit only; Paint = prep + spray.
A8: Bonnet vents | B8: 2 | C8: 1 | D8: 60 | E8: 80 | F8: 0.025 | G8: United Kingdom | H8: =COUNTIF(Catalog!$C:$C,A8) -> 2 | I8: Rough estimate — adjust from first real job. Install = fit only; Paint = prep + spray.
A9: Side vents | B9: 2 | C9: 1 | D9: 60 | E9: 80 | F9: 0.025 | G9: United Kingdom | H9: =COUNTIF(Catalog!$C:$C,A9) -> 2 | I9: Rough estimate — adjust from first real job. Install = fit only; Paint = prep + spray.
A10: Lighting | B10: 3 | C10: 0 | D10: 0 | E10: 100 | F10: 0.025 | G10: United Kingdom | H10: =COUNTIF(Catalog!$C:$C,A10) -> 6 | I10: Rough estimate — adjust from first real job. Install = fit only; Paint = prep + spray.
A11: Roof light bar | B11: 4 | C11: 0 | D11: 0 | E11: 150 | F11: 0.025 | G11: United Kingdom | H11: =COUNTIF(Catalog!$C:$C,A11) -> 3 | I11: Rough estimate — adjust from first real job. Install = fit only; Paint = prep + spray.
A12: Roof rack | B12: 4 | C12: 0 | D12: 0 | E12: 350 | F12: 0.025 | G12: United Kingdom | H12: =COUNTIF(Catalog!$C:$C,A12) -> 1 | I12: Rough estimate — adjust from first real job. Install = fit only; Paint = prep + spray.
A13: Side ladder | B13: 2 | C13: 0 | D13: 0 | E13: 120 | F13: 0.025 | G13: United Kingdom | H13: =COUNTIF(Catalog!$C:$C,A13) -> 1 | I13: Rough estimate — adjust from first real job. Install = fit only; Paint = prep + spray.
... A31: Gear shift trim | B31: 0.5 | C31: 0 | D31: 0 | E31: 30 | F31: 0.025 | G31: United Kingdom | H31: =COUNTIF(Catalog!$C:$C,A31) -> 1 | I31: Rough estimate — adjust from first real job. Install = fit only; Paint = prep + spray.

Sheet Catalog
A1: Group | B1: Sub-type (Shopify tag) | C1: Category | D1: Name | E1: SKU | F1: Sold as set | G1: Platforms | H1: Web price (GBP) | I1: Kit cost (GBP) | J1: Kit cost (USD) | K1: Freight | L1: HTS duty | M1: Additional tariff | N1: Section 232 aluminium | O1: MPF + brokerage | P1: Landed cost | Q1: Parts sell price (retail + landing) | R1: Install hrs | S1: Paint hrs | T1: Labour $ | U1: Paint materials | V1: Install price | W1: Total price | X1: Origin override | Y1: Country of origin | Z1: System price today | AA1: Product URL
A2: Exterior | B2: body-kits | C2: Body kit | D2: INEOS Grenadier (2023 Onwards) Extra Wide Package 1 - Mondial | E2: WAKMF9268M1F-KIT | F2: No | G2: Ineos Grenadier (2023–present) | H2: 6802 | I2: =H2*(1-Assumptions!$B$6) -> 5101.5 | J2: =I2*Assumptions!$B$5 -> 6478.905 | K2: =INDEX(Categories!$E$2:$E$31,MATCH($C2,Categories!$A$2:$A$31,0)) -> 1200 | L2: =J2*INDEX(Categories!$F$2:$F$31,MATCH($C2,Categories!$A$2:$A$31,0)) -> 161.97262 | M2: =J2*INDEX(Origins!$B$2:$B$4,MATCH($Y2,Origins!$A$2:$A$4,0)) -> 647.8905 | N2: =IF($C2="Alloy wheels",J2*Origins!$B$7*INDEX(Origins!$C$2:$C$4,MATCH($Y2,Origins!$A$2:$A$4,0)),0) -> 0 | O2: =J2*Assumptions!$B$7+Assumptions!$B$8/Assumptions!$B$9 -> 47.442927 | P2: =J2+K2+L2+M2+N2+O2 -> 8536.2111 | Q2: =H2*Assumptions!$B$5+K2+L2+M2+N2+O2 -> 10695.846 | R2: =INDEX(Categories!$B$2:$B$31,MATCH($C2,Categories!$A$2:$A$31,0)) -> 24 | S2: =INDEX(Categories!$C$2:$C$31,MATCH($C2,Categories!$A$2:$A$31,0)) -> 16 | T2: =R2*Assumptions!$B$10+S2*Assumptions!$B$11 -> 8000 | U2: =INDEX(Categories!$D$2:$D$31,MATCH($C2,Categories!$A$2:$A$31,0)) -> 1500 | V2: =T2+U2 -> 9500 | W2: =Q2+V2 -> 20195.846 | Y2: =IF($X2="",INDEX(Categories!$G$2:$G$31,MATCH($C2,Categories!$A$2:$A$31,0)),$X2) -> United Kingdom | Z2: 8638.54 | AA2: https://chelseatruckcompany.com/products/ineos-grenadier-extra-wide-package-2-g22-matte-black
A3: Exterior | B3: body-kits | C3: Body kit | D3: INEOS Grenadier (2023 Onwards) Extra Wide Package 2 - G22 | E3: WAKRF9268M1F-KIT | F3: No | G3: Ineos Grenadier (2023–present) | H3: 6802 | I3: =H3*(1-Assumptions!$B$6) -> 5101.5 | J3: =I3*Assumptions!$B$5 -> 6478.905 | K3: =INDEX(Categories!$E$2:$E$31,MATCH($C3,Categories!$A$2:$A$31,0)) -> 1200 | L3: =J3*INDEX(Categories!$F$2:$F$31,MATCH($C3,Categories!$A$2:$A$31,0)) -> 161.97262 | M3: =J3*INDEX(Origins!$B$2:$B$4,MATCH($Y3,Origins!$A$2:$A$4,0)) -> 647.8905 | N3: =IF($C3="Alloy wheels",J3*Origins!$B$7*INDEX(Origins!$C$2:$C$4,MATCH($Y3,Origins!$A$2:$A$4,0)),0) -> 0 | O3: =J3*Assumptions!$B$7+Assumptions!$B$8/Assumptions!$B$9 -> 47.442927 | P3: =J3+K3+L3+M3+N3+O3 -> 8536.2111 | Q3: =H3*Assumptions!$B$5+K3+L3+M3+N3+O3 -> 10695.846 | R3: =INDEX(Categories!$B$2:$B$31,MATCH($C3,Categories!$A$2:$A$31,0)) -> 24 | S3: =INDEX(Categories!$C$2:$C$31,MATCH($C3,Categories!$A$2:$A$31,0)) -> 16 | T3: =R3*Assumptions!$B$10+S3*Assumptions!$B$11 -> 8000 | U3: =INDEX(Categories!$D$2:$D$31,MATCH($C3,Categories!$A$2:$A$31,0)) -> 1500 | V3: =T3+U3 -> 9500 | W3: =Q3+V3 -> 20195.846 | Y3: =IF($X3="",INDEX(Categories!$G$2:$G$31,MATCH($C3,Categories!$A$2:$A$31,0)),$X3) -> United Kingdom | Z3: 8638.54 | AA3: https://chelseatruckcompany.com/products/ineos-grenadier-2023-extra-wide-package-2-g22-matte-black
A4: Exterior | B4: body-kits | C4: Body kit | D4: JEEP WRANGLER JL (2018 Onwards) 2 DOOR BLACK HAWK BODYKIT | E4: JL2DRBH-KIT | F4: No | G4: Jeep Wrangler JL 2 Door (2018–present) | H4: 20406 | I4: =H4*(1-Assumptions!$B$6) -> 15304.5 | J4: =I4*Assumptions!$B$5 -> 19436.715 | K4: =INDEX(Categories!$E$2:$E$31,MATCH($C4,Categories!$A$2:$A$31,0)) -> 1200 | L4: =J4*INDEX(Categories!$F$2:$F$31,MATCH($C4,Categories!$A$2:$A$31,0)) -> 485.91787 | M4: =J4*INDEX(Origins!$B$2:$B$4,MATCH($Y4,Origins!$A$2:$A$4,0)) -> 1943.6715 | N4: =IF($C4="Alloy wheels",J4*Origins!$B$7*INDEX(Origins!$C$2:$C$4,MATCH($Y4,Origins!$A$2:$A$4,0)),0) -> 0 | O4: =J4*Assumptions!$B$7+Assumptions!$B$8/Assumptions!$B$9 -> 92.328781 | P4: =J4+K4+L4+M4+N4+O4 -> 23158.633 | Q4: =H4*Assumptions!$B$5+K4+L4+M4+N4+O4 -> 29637.538 | R4: =INDEX(Categories!$B$2:$B$31,MATCH($C4,Categories!$A$2:$A$31,0)) -> 24 | S4: =INDEX(Categories!$C$2:$C$31,MATCH($C4,Categories!$A$2:$A$31,0)) -> 16 | T4: =R4*Assumptions!$B$10+S4*Assumptions!$B$11 -> 8000 | U4: =INDEX(Categories!$D$2:$D$31,MATCH($C4,Categories!$A$2:$A$31,0)) -> 1500 | V4: =T4+U4 -> 9500 | W4: =Q4+V4 -> 39137.538 | Y4: =IF($X4="",INDEX(Categories!$G$2:$G$31,MATCH($C4,Categories!$A$2:$A$31,0)),$X4) -> United Kingdom | Z4: 25915.62 | AA4: https://chelseatruckcompany.com/products/jeep-wrangler-jl-2018-present-2-door-black-hawk-bodykit
A5: Exterior | B5: body-kits | C5: Body kit | D5: JEEP WRANGLER JL (2018 Onwards) 4 DOOR BLACK HAWK BODYKIT | E5: JL4DRBH-KIT | F5: No | G5: Jeep Wrangler JL 4 Door (2018–present) | H5: 20406 | I5: =H5*(1-Assumptions!$B$6) -> 15304.5 | J5: =I5*Assumptions!$B$5 -> 19436.715 | K5: =INDEX(Categories!$E$2:$E$31,MATCH($C5,Categories!$A$2:$A$31,0)) -> 1200 | L5: =J5*INDEX(Categories!$F$2:$F$31,MATCH($C5,Categories!$A$2:$A$31,0)) -> 485.91787 | M5: =J5*INDEX(Origins!$B$2:$B$4,MATCH($Y5,Origins!$A$2:$A$4,0)) -> 1943.6715 | N5: =IF($C5="Alloy wheels",J5*Origins!$B$7*INDEX(Origins!$C$2:$C$4,MATCH($Y5,Origins!$A$2:$A$4,0)),0) -> 0 | O5: =J5*Assumptions!$B$7+Assumptions!$B$8/Assumptions!$B$9 -> 92.328781 | P5: =J5+K5+L5+M5+N5+O5 -> 23158.633 | Q5: =H5*Assumptions!$B$5+K5+L5+M5+N5+O5 -> 29637.538 | R5: =INDEX(Categories!$B$2:$B$31,MATCH($C5,Categories!$A$2:$A$31,0)) -> 24 | S5: =INDEX(Categories!$C$2:$C$31,MATCH($C5,Categories!$A$2:$A$31,0)) -> 16 | T5: =R5*Assumptions!$B$10+S5*Assumptions!$B$11 -> 8000 | U5: =INDEX(Categories!$D$2:$D$31,MATCH($C5,Categories!$A$2:$A$31,0)) -> 1500 | V5: =T5+U5 -> 9500 | W5: =Q5+V5 -> 39137.538 | Y5: =IF($X5="",INDEX(Categories!$G$2:$G$31,MATCH($C5,Categories!$A$2:$A$31,0)),$X5) -> United Kingdom | Z5: 25915.62 | AA5: https://chelseatruckcompany.com/products/jeep-wrangler-jl-2018-present-4-door-black-hawk-bodykit
A6: Exterior | B6: body-kits | C6: Body kit | D6: JEEP WRANGLER JL (2018 Onwards) 4 DOOR BODYGUARD BODYKIT | E6: BCAJW2VW | F6: No | G6: Jeep Wrangler JL 4 Door (2018–present) | H6: 5102 | I6: =H6*(1-Assumptions!$B$6) -> 3826.5 | J6: =I6*Assumptions!$B$5 -> 4859.655 | K6: =INDEX(Categories!$E$2:$E$31,MATCH($C6,Categories!$A$2:$A$31,0)) -> 1200 | L6: =J6*INDEX(Categories!$F$2:$F$31,MATCH($C6,Categories!$A$2:$A$31,0)) -> 121.49138 | M6: =J6*INDEX(Origins!$B$2:$B$4,MATCH($Y6,Origins!$A$2:$A$4,0)) -> 485.9655 | N6: =IF($C6="Alloy wheels",J6*Origins!$B$7*INDEX(Origins!$C$2:$C$4,MATCH($Y6,Origins!$A$2:$A$4,0)),0) -> 0 | O6: =J6*Assumptions!$B$7+Assumptions!$B$8/Assumptions!$B$9 -> 41.833845 | P6: =J6+K6+L6+M6+N6+O6 -> 6708.9457 | Q6: =H6*Assumptions!$B$5+K6+L6+M6+N6+O6 -> 8328.8307 | R6: =INDEX(Categories!$B$2:$B$31,MATCH($C6,Categories!$A$2:$A$31,0)) -> 24 | S6: =INDEX(Categories!$C$2:$C$31,MATCH($C6,Categories!$A$2:$A$31,0)) -> 16 | T6: =R6*Assumptions!$B$10+S6*Assumptions!$B$11 -> 8000 | U6: =INDEX(Categories!$D$2:$D$31,MATCH($C6,Categories!$A$2:$A$31,0)) -> 1500 | V6: =T6+U6 -> 9500 | W6: =Q6+V6 -> 17828.831 | Y6: =IF($X6="",INDEX(Categories!$G$2:$G$31,MATCH($C6,Categories!$A$2:$A$31,0)),$X6) -> United Kingdom | Z6: 6479.54 | AA6: https://chelseatruckcompany.com/products/jeep-wrangler-jl-2018-present-4-door-bodyguard-bodykit
A7: Exterior | B7: body-kits | C7: Body kit | D7: Land Rover Defender 110 (1991-2016) Wide Track Body Kit | E7: BCALD1PB | F7: No | G7: Land Rover Defender 110 (1991–2016) | H7: 5272 | I7: =H7*(1-Assumptions!$B$6) -> 3954 | J7: =I7*Assumptions!$B$5 -> 5021.58 | K7: =INDEX(Categories!$E$2:$E$31,MATCH($C7,Categories!$A$2:$A$31,0)) -> 1200 | L7: =J7*INDEX(Categories!$F$2:$F$31,MATCH($C7,Categories!$A$2:$A$31,0)) -> 125.5395 | M7: =J7*INDEX(Origins!$B$2:$B$4,MATCH($Y7,Origins!$A$2:$A$4,0)) -> 502.158 | N7: =IF($C7="Alloy wheels",J7*Origins!$B$7*INDEX(Origins!$C$2:$C$4,MATCH($Y7,Origins!$A$2:$A$4,0)),0) -> 0 | O7: =J7*Assumptions!$B$7+Assumptions!$B$8/Assumptions!$B$9 -> 42.394753 | P7: =J7+K7+L7+M7+N7+O7 -> 6891.6723 | Q7: =H7*Assumptions!$B$5+K7+L7+M7+N7+O7 -> 8565.5323 | R7: =INDEX(Categories!$B$2:$B$31,MATCH($C7,Categories!$A$2:$A$31,0)) -> 24 | S7: =INDEX(Categories!$C$2:$C$31,MATCH($C7,Categories!$A$2:$A$31,0)) -> 16 | T7: =R7*Assumptions!$B$10+S7*Assumptions!$B$11 -> 8000 | U7: =INDEX(Categories!$D$2:$D$31,MATCH($C7,Categories!$A$2:$A$31,0)) -> 1500 | V7: =T7+U7 -> 9500 | W7: =Q7+V7 -> 18065.532 | Y7: =IF($X7="",INDEX(Categories!$G$2:$G$31,MATCH($C7,Categories!$A$2:$A$31,0)),$X7) -> United Kingdom | Z7: 6695.44 | AA7: https://chelseatruckcompany.com/products/land-rover-defender-body-kit-110-model-wide-arch-kit
A8: Exterior | B8: body-kits | C8: Body kit | D8: Land Rover Defender 130 (2020 Onwards) Landmark Body Kit | E8: BCKLD2VF-KIT | F8: No | G8: Land Rover Defender 130 (2020–present) | H8: 2948 | I8: =H8*(1-Assumptions!$B$6) -> 2211 | J8: =I8*Assumptions!$B$5 -> 2807.97 | K8: =INDEX(Categories!$E$2:$E$31,MATCH($C8,Categories!$A$2:$A$31,0)) -> 1200 | L8: =J8*INDEX(Categories!$F$2:$F$31,MATCH($C8,Categories!$A$2:$A$31,0)) -> 70.19925 | M8: =J8*INDEX(Origins!$B$2:$B$4,MATCH($Y8,Origins!$A$2:$A$4,0)) -> 280.797 | N8: =IF($C8="Alloy wheels",J8*Origins!$B$7*INDEX(Origins!$C$2:$C$4,MATCH($Y8,Origins!$A$2:$A$4,0)),0) -> 0 | O8: =J8*Assumptions!$B$7+Assumptions!$B$8/Assumptions!$B$9 -> 34.726808 | P8: =J8+K8+L8+M8+N8+O8 -> 4393.6931 | Q8: =H8*Assumptions!$B$5+K8+L8+M8+N8+O8 -> 5329.6831 | R8: =INDEX(Categories!$B$2:$B$31,MATCH($C8,Categories!$A$2:$A$31,0)) -> 24 | S8: =INDEX(Categories!$C$2:$C$31,MATCH($C8,Categories!$A$2:$A$31,0)) -> 16 | T8: =R8*Assumptions!$B$10+S8*Assumptions!$B$11 -> 8000 | U8: =INDEX(Categories!$D$2:$D$31,MATCH($C8,Categories!$A$2:$A$31,0)) -> 1500 | V8: =T8+U8 -> 9500 | W8: =Q8+V8 -> 14829.683 | Y8: =IF($X8="",INDEX(Categories!$G$2:$G$31,MATCH($C8,Categories!$A$2:$A$31,0)),$X8) -> United Kingdom | Z8: 3743.96 | AA8: https://chelseatruckcompany.com/products/land-rover-defender-2020-present-landmark-package
A9: Exterior | B9: body-kits | C9: Body kit | D9: Land Rover Defender 90 (1991-2016) Wide Track Body Kit | E9: BCALD1PB-1 | F9: No | G9: Land Rover Defender 90 (1991–2016) | H9: 4932 | I9: =H9*(1-Assumptions!$B$6) -> 3699 | J9: =I9*Assumptions!$B$5 -> 4697.73 | K9: =INDEX(Categories!$E$2:$E$31,MATCH($C9,Categories!$A$2:$A$31,0)) -> 1200 | L9: =J9*INDEX(Categories!$F$2:$F$31,MATCH($C9,Categories!$A$2:$A$31,0)) -> 117.44325 | M9: =J9*INDEX(Origins!$B$2:$B$4,MATCH($Y9,Origins!$A$2:$A$4,0)) -> 469.773 | N9: =IF($C9="Alloy wheels",J9*Origins!$B$7*INDEX(Origins!$C$2:$C$4,MATCH($Y9,Origins!$A$2:$A$4,0)),0) -> 0 | O9: =J9*Assumptions!$B$7+Assumptions!$B$8/Assumptions!$B$9 -> 41.272937 | P9: =J9+K9+L9+M9+N9+O9 -> 6526.2192 | Q9: =H9*Assumptions!$B$5+K9+L9+M9+N9+O9 -> 8092.1292 | R9: =INDEX(Categories!$B$2:$B$31,MATCH($C9,Categories!$A$2:$A$31,0)) -> 24 | S9: =INDEX(Categories!$C$2:$C$31,MATCH($C9,Categories!$A$2:$A$31,0)) -> 16 | T9: =R9*Assumptions!$B$10+S9*Assumptions!$B$11 -> 8000 | U9: =INDEX(Categories!$D$2:$D$31,MATCH($C9,Categories!$A$2:$A$31,0)) -> 1500 | V9: =T9+U9 -> 9500 | W9: =Q9+V9 -> 17592.129 | Y9: =IF($X9="",INDEX(Categories!$G$2:$G$31,MATCH($C9,Categories!$A$2:$A$31,0)),$X9) -> United Kingdom | Z9: 6263.64 | AA9: https://chelseatruckcompany.com/products/wide-track-arch-kit-90-defender-wide-track-body-kit
A10: Exterior | B10: body-kits | C10: Body kit | D10: Landmark Body Kit for Land Rover Defender (2020 Onwards) | E10: BCKLD2VF-KIT | F10: No | G10: Land Rover Defender 110 (2020–present); Land Rover Defender 90 (2020–present) | H10: 2948 | I10: =H10*(1-Assumptions!$B$6) -> 2211 | J10: =I10*Assumptions!$B$5 -> 2807.97 | K10: =INDEX(Categories!$E$2:$E$31,MATCH($C10,Categories!$A$2:$A$31,0)) -> 1200 | L10: =J10*INDEX(Categories!$F$2:$F$31,MATCH($C10,Categories!$A$2:$A$31,0)) -> 70.19925 | M10: =J10*INDEX(Origins!$B$2:$B$4,MATCH($Y10,Origins!$A$2:$A$4,0)) -> 280.797 | N10: =IF($C10="Alloy wheels",J10*Origins!$B$7*INDEX(Origins!$C$2:$C$4,MATCH($Y10,Origins!$A$2:$A$4,0)),0) -> 0 | O10: =J10*Assumptions!$B$7+Assumptions!$B$8/Assumptions!$B$9 -> 34.726808 | P10: =J10+K10+L10+M10+N10+O10 -> 4393.6931 | Q10: =H10*Assumptions!$B$5+K10+L10+M10+N10+O10 -> 5329.6831 | R10: =INDEX(Categories!$B$2:$B$31,MATCH($C10,Categories!$A$2:$A$31,0)) -> 24 | S10: =INDEX(Categories!$C$2:$C$31,MATCH($C10,Categories!$A$2:$A$31,0)) -> 16 | T10: =R10*Assumptions!$B$10+S10*Assumptions!$B$11 -> 8000 | U10: =INDEX(Categories!$D$2:$D$31,MATCH($C10,Categories!$A$2:$A$31,0)) -> 1500 | V10: =T10+U10 -> 9500 | W10: =Q10+V10 -> 14829.683 | Y10: =IF($X10="",INDEX(Categories!$G$2:$G$31,MATCH($C10,Categories!$A$2:$A$31,0)),$X10) -> United Kingdom | Z10: 3743.96 | AA10: https://chelseatruckcompany.com/products/land-rover-defender-2020-present-landmark-package
A11: Exterior | B11: body-kits | C11: Body kit | D11: MERCEDES G-WAGON (2018 Onwards) G63 AMG EXPOSED CARBON WHEEL ARCHES | E11: GW18ECWA | F11: No | G11: Mercedes-Benz G-Wagon G63 (2018–present) | H11: 5442 | I11: =H11*(1-Assumptions!$B$6) -> 4081.5 | J11: =I11*Assumptions!$B$5 -> 5183.505 | K11: =INDEX(Categories!$E$2:$E$31,MATCH($C11,Categories!$A$2:$A$31,0)) -> 1200 | L11: =J11*INDEX(Categories!$F$2:$F$31,MATCH($C11,Categories!$A$2:$A$31,0)) -> 129.58763 | M11: =J11*INDEX(Origins!$B$2:$B$4,MATCH($Y11,Origins!$A$2:$A$4,0)) -> 518.3505 | N11: =IF($C11="Alloy wheels",J11*Origins!$B$7*INDEX(Origins!$C$2:$C$4,MATCH($Y11,Origins!$A$2:$A$4,0)),0) -> 0 | O11: =J11*Assumptions!$B$7+Assumptions!$B$8/Assumptions!$B$9 -> 42.955661 | P11: =J11+K11+L11+M11+N11+O11 -> 7074.3988 | Q11: =H11*Assumptions!$B$5+K11+L11+M11+N11+O11 -> 8802.2338 | R11: =INDEX(Categories!$B$2:$B$31,MATCH($C11,Categories!$A$2:$A$31,0)) -> 24 | S11: =INDEX(Categories!$C$2:$C$31,MATCH($C11,Categories!$A$2:$A$31,0)) -> 16 | T11: =R11*Assumptions!$B$10+S11*Assumptions!$B$11 -> 8000 | U11: =INDEX(Categories!$D$2:$D$31,MATCH($C11,Categories!$A$2:$A$31,0)) -> 1500 | V11: =T11+U11 -> 9500 | W11: =Q11+V11 -> 18302.234 | Y11: =IF($X11="",INDEX(Categories!$G$2:$G$31,MATCH($C11,Categories!$A$2:$A$31,0)),$X11) -> United Kingdom | Z11: 6911.34 | AA11: https://chelseatruckcompany.com/products/mercedes-g-wagon-2018-present-exposed-carbon-wheel-arches
A12: Exterior | B12: body-kits | C12: Body kit | D12: Mercedes G63 AMG Hammer Edition Carbon Body Kit (2018 Onwards) | E12: GW18ECWA-KIT | F12: No | G12: Mercedes-Benz G-Wagon G63 (2018–present) | H12: 17005 | I12: =H12*(1-Assumptions!$B$6) -> 12753.75 | J12: =I12*Assumptions!$B$5 -> 16197.263 | K12: =INDEX(Categories!$E$2:$E$31,MATCH($C12,Categories!$A$2:$A$31,0)) -> 1200 | L12: =J12*INDEX(Categories!$F$2:$F$31,MATCH($C12,Categories!$A$2:$A$31,0)) -> 404.93156 | M12: =J12*INDEX(Origins!$B$2:$B$4,MATCH($Y12,Origins!$A$2:$A$4,0)) -> 1619.7262 | N12: =IF($C12="Alloy wheels",J12*Origins!$B$7*INDEX(Origins!$C$2:$C$4,MATCH($Y12,Origins!$A$2:$A$4,0)),0) -> 0 | O12: =J12*Assumptions!$B$7+Assumptions!$B$8/Assumptions!$B$9 -> 81.107317 | P12: =J12+K12+L12+M12+N12+O12 -> 19503.028 | Q12: =H12*Assumptions!$B$5+K12+L12+M12+N12+O12 -> 24902.115 | R12: =INDEX(Categories!$B$2:$B$31,MATCH($C12,Categories!$A$2:$A$31,0)) -> 24 | S12: =INDEX(Categories!$C$2:$C$31,MATCH($C12,Categories!$A$2:$A$31,0)) -> 16 | T12: =R12*Assumptions!$B$10+S12*Assumptions!$B$11 -> 8000 | U12: =INDEX(Categories!$D$2:$D$31,MATCH($C12,Categories!$A$2:$A$31,0)) -> 1500 | V12: =T12+U12 -> 9500 | W12: =Q12+V12 -> 34402.115 | Y12: =IF($X12="",INDEX(Categories!$G$2:$G$31,MATCH($C12,Categories!$A$2:$A$31,0)),$X12) -> United Kingdom | Z12: 21596.35 | AA12: https://chelseatruckcompany.com/products/mercedes-g-wagon-2018-present-hammer-edition-iii-exposed-carbon-body-kit
A13: Exterior | B13: wheel-arches | C13: Wheel arches | D13: INEOS Grenadier (2023 Onwards) 15mm Wheel Arches | E13: BCSIG2AS1-15-KIT | F13: No | G13: Ineos Grenadier (2023–present) | H13: 907 | I13: =H13*(1-Assumptions!$B$6) -> 680.25 | J13: =I13*Assumptions!$B$5 -> 863.9175 | K13: =INDEX(Categories!$E$2:$E$31,MATCH($C13,Categories!$A$2:$A$31,0)) -> 500 | L13: =J13*INDEX(Categories!$F$2:$F$31,MATCH($C13,Categories!$A$2:$A$31,0)) -> 21.597938 | M13: =J13*INDEX(Origins!$B$2:$B$4,MATCH($Y13,Origins!$A$2:$A$4,0)) -> 86.39175 | N13: =IF($C13="Alloy wheels",J13*Origins!$B$7*INDEX(Origins!$C$2:$C$4,MATCH($Y13,Origins!$A$2:$A$4,0)),0) -> 0 | O13: =J13*Assumptions!$B$7+Assumptions!$B$8/Assumptions!$B$9 -> 27.99261 | P13: =J13+K13+L13+M13+N13+O13 -> 1499.8998 | Q13: =H13*Assumptions!$B$5+K13+L13+M13+N13+O13 -> 1787.8723 | R13: =INDEX(Categories!$B$2:$B$31,MATCH($C13,Categories!$A$2:$A$31,0)) -> 10 | S13: =INDEX(Categories!$C$2:$C$31,MATCH($C13,Categories!$A$2:$A$31,0)) -> 6 | T13: =R13*Assumptions!$B$10+S13*Assumptions!$B$11 -> 3200 | U13: =INDEX(Categories!$D$2:$D$31,MATCH($C13,Categories!$A$2:$A$31,0)) -> 600 | V13: =T13+U13 -> 3800 | W13: =Q13+V13 -> 5587.8723 | Y13: =IF($X13="",INDEX(Categories!$G$2:$G$31,MATCH($C13,Categories!$A$2:$A$31,0)),$X13) -> United Kingdom | Z13: 1151.89 | AA13: https://chelseatruckcompany.com/products/ineos-grenadier-2023-present-15mm-wheel-arches
... A98: Alloy wheels | B98: wheels | C98: Alloy wheels | D98: INEOS Grenadier (2023 Onwards) RS-Forged Alloy Wheels - Hammerhead | E98: WACHF8468S1R | F98: No | G98: Ineos Grenadier (2023–present) | H98: 567 | I98: =H98*(1-Assumptions!$B$6) -> 425.25 | J98: =I98*Assumptions!$B$5 -> 540.0675 | K98: =INDEX(Categories!$E$2:$E$31,MATCH($C98,Categories!$A$2:$A$31,0)) -> 150 | L98: =J98*INDEX(Categories!$F$2:$F$31,MATCH($C98,Categories!$A$2:$A$31,0)) -> 13.501687 | M98: =J98*INDEX(Origins!$B$2:$B$4,MATCH($Y98,Origins!$A$2:$A$4,0)) -> 81.010125 | N98: =IF($C98="Alloy wheels",J98*Origins!$B$7*INDEX(Origins!$C$2:$C$4,MATCH($Y98,Origins!$A$2:$A$4,0)),0) -> 108.0135 | O98: =J98*Assumptions!$B$7+Assumptions!$B$8/Assumptions!$B$9 -> 26.870794 | P98: =J98+K98+L98+M98+N98+O98 -> 919.46361 | Q98: =H98*Assumptions!$B$5+K98+L98+M98+N98+O98 -> 1099.4861 | R98: =INDEX(Categories!$B$2:$B$31,MATCH($C98,Categories!$A$2:$A$31,0)) -> 2 | S98: =INDEX(Categories!$C$2:$C$31,MATCH($C98,Categories!$A$2:$A$31,0)) -> 0 | T98: =R98*Assumptions!$B$10+S98*Assumptions!$B$11 -> 400 | U98: =INDEX(Categories!$D$2:$D$31,MATCH($C98,Categories!$A$2:$A$31,0)) -> 0 | V98: =T98+U98 -> 400 | W98: =Q98+V98 -> 1499.4861 | Y98: =IF($X98="",INDEX(Categories!$G$2:$G$31,MATCH($C98,Categories!$A$2:$A$31,0)),$X98) -> Taiwan | Z98: 720.09 | AA98: https://chelseatruckcompany.com/products/ineos-grenadier-2023-present-hammerhead-rs-forged-light-alloy-wheels-ineos-grenadier-wheel-packages
A99: Alloy wheels | C99: Alloy wheels | D99: INEOS Grenadier (2023 Onwards) RS-Forged Alloy Wheels - Mondial Retro (WAKRF9468M1F-1) | E99: WAKRF9468M1F-1 | F99: No | G99: Ineos Grenadier (2023–present) | H99: 454 | I99: =H99*(1-Assumptions!$B$6) -> 340.5 | J99: =I99*Assumptions!$B$5 -> 432.435 | K99: =INDEX(Categories!$E$2:$E$31,MATCH($C99,Categories!$A$2:$A$31,0)) -> 150 | L99: =J99*INDEX(Categories!$F$2:$F$31,MATCH($C99,Categories!$A$2:$A$31,0)) -> 10.810875 | M99: =J99*INDEX(Origins!$B$2:$B$4,MATCH($Y99,Origins!$A$2:$A$4,0)) -> 64.86525 | N99: =IF($C99="Alloy wheels",J99*Origins!$B$7*INDEX(Origins!$C$2:$C$4,MATCH($Y99,Origins!$A$2:$A$4,0)),0) -> 86.487 | O99: =J99*Assumptions!$B$7+Assumptions!$B$8/Assumptions!$B$9 -> 26.497955 | P99: =J99+K99+L99+M99+N99+O99 -> 771.09608 | Q99: =H99*Assumptions!$B$5+K99+L99+M99+N99+O99 -> 915.24108 | R99: =INDEX(Categories!$B$2:$B$31,MATCH($C99,Categories!$A$2:$A$31,0)) -> 2 | S99: =INDEX(Categories!$C$2:$C$31,MATCH($C99,Categories!$A$2:$A$31,0)) -> 0 | T99: =R99*Assumptions!$B$10+S99*Assumptions!$B$11 -> 400 | U99: =INDEX(Categories!$D$2:$D$31,MATCH($C99,Categories!$A$2:$A$31,0)) -> 0 | V99: =T99+U99 -> 400 | W99: =Q99+V99 -> 1315.2411 | Y99: =IF($X99="",INDEX(Categories!$G$2:$G$31,MATCH($C99,Categories!$A$2:$A$31,0)),$X99) -> Taiwan | Z99: 576.58 | AA99: https://chelseatruckcompany.com/products/ineos-grenadier-2023-present-mondial-retro-rs-forged-light-alloy-wheels-matte-ineos-alloy-wheels
A100: Alloy wheels | C100: Alloy wheels | D100: INEOS Grenadier (2023 Onwards) RS-Forged Alloy Wheels - Mondial Retro (WAKRF9468S1F-2) | E100: WAKRF9468S1F-2 | F100: No | G100: Ineos Grenadier (2023–present) | H100: 567 | I100: =H100*(1-Assumptions!$B$6) -> 425.25 | J100: =I100*Assumptions!$B$5 -> 540.0675 | K100: =INDEX(Categories!$E$2:$E$31,MATCH($C100,Categories!$A$2:$A$31,0)) -> 150 | L100: =J100*INDEX(Categories!$F$2:$F$31,MATCH($C100,Categories!$A$2:$A$31,0)) -> 13.501687 | M100: =J100*INDEX(Origins!$B$2:$B$4,MATCH($Y100,Origins!$A$2:$A$4,0)) -> 81.010125 | N100: =IF($C100="Alloy wheels",J100*Origins!$B$7*INDEX(Origins!$C$2:$C$4,MATCH($Y100,Origins!$A$2:$A$4,0)),0) -> 108.0135 | O100: =J100*Assumptions!$B$7+Assumptions!$B$8/Assumptions!$B$9 -> 26.870794 | P100: =J100+K100+L100+M100+N100+O100 -> 919.46361 | Q100: =H100*Assumptions!$B$5+K100+L100+M100+N100+O100 -> 1099.4861 | R100: =INDEX(Categories!$B$2:$B$31,MATCH($C100,Categories!$A$2:$A$31,0)) -> 2 | S100: =INDEX(Categories!$C$2:$C$31,MATCH($C100,Categories!$A$2:$A$31,0)) -> 0 | T100: =R100*Assumptions!$B$10+S100*Assumptions!$B$11 -> 400 | U100: =INDEX(Categories!$D$2:$D$31,MATCH($C100,Categories!$A$2:$A$31,0)) -> 0 | V100: =T100+U100 -> 400 | W100: =Q100+V100 -> 1499.4861 | Y100: =IF($X100="",INDEX(Categories!$G$2:$G$31,MATCH($C100,Categories!$A$2:$A$31,0)),$X100) -> Taiwan | Z100: 720.09 | AA100: https://chelseatruckcompany.com/products/ineos-grenadier-2023-present-mondial-retro-rs-forged-light-alloy-wheels-grenadier-wheels
A101: Alloy wheels | B101: wheels | C101: Alloy wheels | D101: Jeep Wrangler JL (2018 Onwards) Alloy Wheels - RS 3.0 | E101: WAK3F9457A1C | F101: No | G101: Jeep Wrangler JL 2 Door (2018–present); Jeep Wrangler JL 4 Door (2018–present) | H101: 284 | I101: =H101*(1-Assumptions!$B$6) -> 213 | J101: =I101*Assumptions!$B$5 -> 270.51 | K101: =INDEX(Categories!$E$2:$E$31,MATCH($C101,Categories!$A$2:$A$31,0)) -> 150 | L101: =J101*INDEX(Categories!$F$2:$F$31,MATCH($C101,Categories!$A$2:$A$31,0)) -> 6.76275 | M101: =J101*INDEX(Origins!$B$2:$B$4,MATCH($Y101,Origins!$A$2:$A$4,0)) -> 40.5765 | N101: =IF($C101="Alloy wheels",J101*Origins!$B$7*INDEX(Origins!$C$2:$C$4,MATCH($Y101,Origins!$A$2:$A$4,0)),0) -> 54.102 | O101: =J101*Assumptions!$B$7+Assumptions!$B$8/Assumptions!$B$9 -> 25.937047 | P101: =J101+K101+L101+M101+N101+O101 -> 547.8883 | Q101: =H101*Assumptions!$B$5+K101+L101+M101+N101+O101 -> 638.0583 | R101: =INDEX(Categories!$B$2:$B$31,MATCH($C101,Categories!$A$2:$A$31,0)) -> 2 | S101: =INDEX(Categories!$C$2:$C$31,MATCH($C101,Categories!$A$2:$A$31,0)) -> 0 | T101: =R101*Assumptions!$B$10+S101*Assumptions!$B$11 -> 400 | U101: =INDEX(Categories!$D$2:$D$31,MATCH($C101,Categories!$A$2:$A$31,0)) -> 0 | V101: =T101+U101 -> 400 | W101: =Q101+V101 -> 1038.0583 | Y101: =IF($X101="",INDEX(Categories!$G$2:$G$31,MATCH($C101,Categories!$A$2:$A$31,0)),$X101) -> Taiwan | Z101: 360.68 | AA101: https://chelseatruckcompany.com/products/jeep-wrangler-jl-2018-present-rs-3-0-alloy-wheels-1
A102: Alloy wheels | B102: wheels | C102: Alloy wheels | D102: Jeep Wrangler JL (2018 Onwards) RS-Forged Alloy Wheels - British Heritage (EX902SB01) | E102: EX902SB01 | F102: No | G102: Jeep Wrangler JL 2 Door (2018–present); Jeep Wrangler JL 4 Door (2018–present) | H102: 737 | I102: =H102*(1-Assumptions!$B$6) -> 552.75 | J102: =I102*Assumptions!$B$5 -> 701.9925 | K102: =INDEX(Categories!$E$2:$E$31,MATCH($C102,Categories!$A$2:$A$31,0)) -> 150 | L102: =J102*INDEX(Categories!$F$2:$F$31,MATCH($C102,Categories!$A$2:$A$31,0)) -> 17.549813 | M102: =J102*INDEX(Origins!$B$2:$B$4,MATCH($Y102,Origins!$A$2:$A$4,0)) -> 105.29887 | N102: =IF($C102="Alloy wheels",J102*Origins!$B$7*INDEX(Origins!$C$2:$C$4,MATCH($Y102,Origins!$A$2:$A$4,0)),0) -> 140.3985 | O102: =J102*Assumptions!$B$7+Assumptions!$B$8/Assumptions!$B$9 -> 27.431702 | P102: =J102+K102+L102+M102+N102+O102 -> 1142.6714 | Q102: =H102*Assumptions!$B$5+K102+L102+M102+N102+O102 -> 1376.6689 | R102: =INDEX(Categories!$B$2:$B$31,MATCH($C102,Categories!$A$2:$A$31,0)) -> 2 | S102: =INDEX(Categories!$C$2:$C$31,MATCH($C102,Categories!$A$2:$A$31,0)) -> 0 | T102: =R102*Assumptions!$B$10+S102*Assumptions!$B$11 -> 400 | U102: =INDEX(Categories!$D$2:$D$31,MATCH($C102,Categories!$A$2:$A$31,0)) -> 0 | V102: =T102+U102 -> 400 | W102: =Q102+V102 -> 1776.6689 | Y102: =IF($X102="",INDEX(Categories!$G$2:$G$31,MATCH($C102,Categories!$A$2:$A$31,0)),$X102) -> Taiwan | Z102: 935.99 | AA102: https://chelseatruckcompany.com/products/jeep-wrangler-jl-2018-present-expedition-alloy-wheels
A103: Alloy wheels | B103: wheels | C103: Alloy wheels | D103: Jeep Wrangler JL (2018 Onwards) RS-Forged Alloy Wheels - British Heritage (WACHF9357B1R-1) | E103: WACHF9357B1R-1 | F103: No | G103: Jeep Wrangler JL 2 Door (2018–present); Jeep Wrangler JL 4 Door (2018–present) | H103: 567 | I103: =H103*(1-Assumptions!$B$6) -> 425.25 | J103: =I103*Assumptions!$B$5 -> 540.0675 | K103: =INDEX(Categories!$E$2:$E$31,MATCH($C103,Categories!$A$2:$A$31,0)) -> 150 | L103: =J103*INDEX(Categories!$F$2:$F$31,MATCH($C103,Categories!$A$2:$A$31,0)) -> 13.501687 | M103: =J103*INDEX(Origins!$B$2:$B$4,MATCH($Y103,Origins!$A$2:$A$4,0)) -> 81.010125 | N103: =IF($C103="Alloy wheels",J103*Origins!$B$7*INDEX(Origins!$C$2:$C$4,MATCH($Y103,Origins!$A$2:$A$4,0)),0) -> 108.0135 | O103: =J103*Assumptions!$B$7+Assumptions!$B$8/Assumptions!$B$9 -> 26.870794 | P103: =J103+K103+L103+M103+N103+O103 -> 919.46361 | Q103: =H103*Assumptions!$B$5+K103+L103+M103+N103+O103 -> 1099.4861 | R103: =INDEX(Categories!$B$2:$B$31,MATCH($C103,Categories!$A$2:$A$31,0)) -> 2 | S103: =INDEX(Categories!$C$2:$C$31,MATCH($C103,Categories!$A$2:$A$31,0)) -> 0 | T103: =R103*Assumptions!$B$10+S103*Assumptions!$B$11 -> 400 | U103: =INDEX(Categories!$D$2:$D$31,MATCH($C103,Categories!$A$2:$A$31,0)) -> 0 | V103: =T103+U103 -> 400 | W103: =Q103+V103 -> 1499.4861 | Y103: =IF($X103="",INDEX(Categories!$G$2:$G$31,MATCH($C103,Categories!$A$2:$A$31,0)),$X103) -> Taiwan | Z103: 720.09 | AA103: https://chelseatruckcompany.com/products/jeep-wrangler-jl-2018-present-heritage-rs-forged-alloy-wheels
A104: Alloy wheels | B104: wheels | C104: Alloy wheels | D104: Jeep Wrangler JL (2018 Onwards) RS-Forged Alloy Wheels - G22 DC | E104: WACJF9357S1C-1 | F104: No | G104: Jeep Wrangler JL 2 Door (2018–present); Jeep Wrangler JL 4 Door (2018–present) | H104: 567 | I104: =H104*(1-Assumptions!$B$6) -> 425.25 | J104: =I104*Assumptions!$B$5 -> 540.0675 | K104: =INDEX(Categories!$E$2:$E$31,MATCH($C104,Categories!$A$2:$A$31,0)) -> 150 | L104: =J104*INDEX(Categories!$F$2:$F$31,MATCH($C104,Categories!$A$2:$A$31,0)) -> 13.501687 | M104: =J104*INDEX(Origins!$B$2:$B$4,MATCH($Y104,Origins!$A$2:$A$4,0)) -> 81.010125 | N104: =IF($C104="Alloy wheels",J104*Origins!$B$7*INDEX(Origins!$C$2:$C$4,MATCH($Y104,Origins!$A$2:$A$4,0)),0) -> 108.0135 | O104: =J104*Assumptions!$B$7+Assumptions!$B$8/Assumptions!$B$9 -> 26.870794 | P104: =J104+K104+L104+M104+N104+O104 -> 919.46361 | Q104: =H104*Assumptions!$B$5+K104+L104+M104+N104+O104 -> 1099.4861 | R104: =INDEX(Categories!$B$2:$B$31,MATCH($C104,Categories!$A$2:$A$31,0)) -> 2 | S104: =INDEX(Categories!$C$2:$C$31,MATCH($C104,Categories!$A$2:$A$31,0)) -> 0 | T104: =R104*Assumptions!$B$10+S104*Assumptions!$B$11 -> 400 | U104: =INDEX(Categories!$D$2:$D$31,MATCH($C104,Categories!$A$2:$A$31,0)) -> 0 | V104: =T104+U104 -> 400 | W104: =Q104+V104 -> 1499.4861 | Y104: =IF($X104="",INDEX(Categories!$G$2:$G$31,MATCH($C104,Categories!$A$2:$A$31,0)),$X104) -> Taiwan | Z104: 720.09 | AA104: https://chelseatruckcompany.com/products/jeep-wrangler-jl-2018-present-g22-dc-forged-light-alloy-wheels
A105: Alloy wheels | B105: wheels | C105: Alloy wheels | D105: Jeep Wrangler JL (2018 Onwards) RS-Forged Alloy Wheels - Mondial | E105: 1994950SB2 | F105: No | G105: Jeep Wrangler JL 2 Door (2018–present); Jeep Wrangler JL 4 Door (2018–present) | H105: 341 | I105: =H105*(1-Assumptions!$B$6) -> 255.75 | J105: =I105*Assumptions!$B$5 -> 324.8025 | K105: =INDEX(Categories!$E$2:$E$31,MATCH($C105,Categories!$A$2:$A$31,0)) -> 150 | L105: =J105*INDEX(Categories!$F$2:$F$31,MATCH($C105,Categories!$A$2:$A$31,0)) -> 8.1200625 | M105: =J105*INDEX(Origins!$B$2:$B$4,MATCH($Y105,Origins!$A$2:$A$4,0)) -> 48.720375 | N105: =IF($C105="Alloy wheels",J105*Origins!$B$7*INDEX(Origins!$C$2:$C$4,MATCH($Y105,Origins!$A$2:$A$4,0)),0) -> 64.9605 | O105: =J105*Assumptions!$B$7+Assumptions!$B$8/Assumptions!$B$9 -> 26.125116 | P105: =J105+K105+L105+M105+N105+O105 -> 622.72855 | Q105: =H105*Assumptions!$B$5+K105+L105+M105+N105+O105 -> 730.99605 | R105: =INDEX(Categories!$B$2:$B$31,MATCH($C105,Categories!$A$2:$A$31,0)) -> 2 | S105: =INDEX(Categories!$C$2:$C$31,MATCH($C105,Categories!$A$2:$A$31,0)) -> 0 | T105: =R105*Assumptions!$B$10+S105*Assumptions!$B$11 -> 400 | U105: =INDEX(Categories!$D$2:$D$31,MATCH($C105,Categories!$A$2:$A$31,0)) -> 0 | V105: =T105+U105 -> 400 | W105: =Q105+V105 -> 1130.9961 | Y105: =IF($X105="",INDEX(Categories!$G$2:$G$31,MATCH($C105,Categories!$A$2:$A$31,0)),$X105) -> Taiwan | Z105: 433.07 | AA105: https://chelseatruckcompany.com/products/jeep-wrangler-jl-2018-present-mondial-heavy-duty-rs-forged-light-alloy-wheels
A106: Alloy wheels | B106: wheels | C106: Alloy wheels | D106: Jeep Wrangler JL (2018 Onwards) RS-Forged Alloy Wheels - Mondial Retro | E106: WACMF9457M1C | F106: No | G106: Jeep Wrangler JL 2 Door (2018–present); Jeep Wrangler JL 4 Door (2018–present) | H106: 282 | I106: =H106*(1-Assumptions!$B$6) -> 211.5 | J106: =I106*Assumptions!$B$5 -> 268.605 | K106: =INDEX(Categories!$E$2:$E$31,MATCH($C106,Categories!$A$2:$A$31,0)) -> 150 | L106: =J106*INDEX(Categories!$F$2:$F$31,MATCH($C106,Categories!$A$2:$A$31,0)) -> 6.715125 | M106: =J106*INDEX(Origins!$B$2:$B$4,MATCH($Y106,Origins!$A$2:$A$4,0)) -> 40.29075 | N106: =IF($C106="Alloy wheels",J106*Origins!$B$7*INDEX(Origins!$C$2:$C$4,MATCH($Y106,Origins!$A$2:$A$4,0)),0) -> 53.721 | O106: =J106*Assumptions!$B$7+Assumptions!$B$8/Assumptions!$B$9 -> 25.930448 | P106: =J106+K106+L106+M106+N106+O106 -> 545.26232 | Q106: =H106*Assumptions!$B$5+K106+L106+M106+N106+O106 -> 634.79732 | R106: =INDEX(Categories!$B$2:$B$31,MATCH($C106,Categories!$A$2:$A$31,0)) -> 2 | S106: =INDEX(Categories!$C$2:$C$31,MATCH($C106,Categories!$A$2:$A$31,0)) -> 0 | T106: =R106*Assumptions!$B$10+S106*Assumptions!$B$11 -> 400 | U106: =INDEX(Categories!$D$2:$D$31,MATCH($C106,Categories!$A$2:$A$31,0)) -> 0 | V106: =T106+U106 -> 400 | W106: =Q106+V106 -> 1034.7973 | Y106: =IF($X106="",INDEX(Categories!$G$2:$G$31,MATCH($C106,Categories!$A$2:$A$31,0)),$X106) -> Taiwan | Z106: 358.14 | AA106: https://chelseatruckcompany.com/products/jeep-wrangler-mondial-retro-light-alloy-wheels
A107: Alloy wheels | B107: wheels | C107: Alloy wheels | D107: Land Rover Defender (1991-2016) Alloy Wheels - 1983 | E107: WACDF8151M1C-2 | F107: No | G107: Land Rover Defender 110 (1991–2016); Land Rover Defender 90 (1991–2016) | H107: 613 | I107: =H107*(1-Assumptions!$B$6) -> 459.75 | J107: =I107*Assumptions!$B$5 -> 583.8825 | K107: =INDEX(Categories!$E$2:$E$31,MATCH($C107,Categories!$A$2:$A$31,0)) -> 150 | L107: =J107*INDEX(Categories!$F$2:$F$31,MATCH($C107,Categories!$A$2:$A$31,0)) -> 14.597062 | M107: =J107*INDEX(Origins!$B$2:$B$4,MATCH($Y107,Origins!$A$2:$A$4,0)) -> 87.582375 | N107: =IF($C107="Alloy wheels",J107*Origins!$B$7*INDEX(Origins!$C$2:$C$4,MATCH($Y107,Origins!$A$2:$A$4,0)),0) -> 116.7765 | O107: =J107*Assumptions!$B$7+Assumptions!$B$8/Assumptions!$B$9 -> 27.022569 | P107: =J107+K107+L107+M107+N107+O107 -> 979.86101 | Q107: =H107*Assumptions!$B$5+K107+L107+M107+N107+O107 -> 1174.4885 | R107: =INDEX(Categories!$B$2:$B$31,MATCH($C107,Categories!$A$2:$A$31,0)) -> 2 | S107: =INDEX(Categories!$C$2:$C$31,MATCH($C107,Categories!$A$2:$A$31,0)) -> 0 | T107: =R107*Assumptions!$B$10+S107*Assumptions!$B$11 -> 400 | U107: =INDEX(Categories!$D$2:$D$31,MATCH($C107,Categories!$A$2:$A$31,0)) -> 0 | V107: =T107+U107 -> 400 | W107: =Q107+V107 -> 1574.4885 | Y107: =IF($X107="",INDEX(Categories!$G$2:$G$31,MATCH($C107,Categories!$A$2:$A$31,0)),$X107) -> Taiwan | Z107: 778.51 | AA107: https://chelseatruckcompany.com/products/land-rover-defender-1983-matt-black-alloy-wheel-set-of-4-defender-wheels
A108: Alloy wheels | B108: wheels | C108: Alloy wheels | D108: Land Rover Defender (1991-2016) Alloy Wheels - Huntsman 1945 Retro Classic | E108: WACDF8151M1C | F108: No | G108: Land Rover Defender 110 (1991–2016); Land Rover Defender 90 (1991–2016) | H108: 539 | I108: =H108*(1-Assumptions!$B$6) -> 404.25 | J108: =I108*Assumptions!$B$5 -> 513.3975 | K108: =INDEX(Categories!$E$2:$E$31,MATCH($C108,Categories!$A$2:$A$31,0)) -> 150 | L108: =J108*INDEX(Categories!$F$2:$F$31,MATCH($C108,Categories!$A$2:$A$31,0)) -> 12.834938 | M108: =J108*INDEX(Origins!$B$2:$B$4,MATCH($Y108,Origins!$A$2:$A$4,0)) -> 77.009625 | N108: =IF($C108="Alloy wheels",J108*Origins!$B$7*INDEX(Origins!$C$2:$C$4,MATCH($Y108,Origins!$A$2:$A$4,0)),0) -> 102.6795 | O108: =J108*Assumptions!$B$7+Assumptions!$B$8/Assumptions!$B$9 -> 26.778409 | P108: =J108+K108+L108+M108+N108+O108 -> 882.69997 | Q108: =H108*Assumptions!$B$5+K108+L108+M108+N108+O108 -> 1053.8325 | R108: =INDEX(Categories!$B$2:$B$31,MATCH($C108,Categories!$A$2:$A$31,0)) -> 2 | S108: =INDEX(Categories!$C$2:$C$31,MATCH($C108,Categories!$A$2:$A$31,0)) -> 0 | T108: =R108*Assumptions!$B$10+S108*Assumptions!$B$11 -> 400 | U108: =INDEX(Categories!$D$2:$D$31,MATCH($C108,Categories!$A$2:$A$31,0)) -> 0 | V108: =T108+U108 -> 400 | W108: =Q108+V108 -> 1453.8325 | Y108: =IF($X108="",INDEX(Categories!$G$2:$G$31,MATCH($C108,Categories!$A$2:$A$31,0)),$X108) -> Taiwan | Z108: 684.53 | AA108: https://chelseatruckcompany.com/products/defender-1945-retro-classic-alloy-wheel-retro-defender-alloy-wheels
A109: Alloy wheels | B109: wheels | C109: Alloy wheels | D109: Land Rover Defender (1991-2016) RS-Forged Alloy Wheels - Mondial Retro | E109: WACMF9251V1C | F109: No | G109: Land Rover Defender 110 (1991–2016); Land Rover Defender 90 (1991–2016) | H109: 681 | I109: =H109*(1-Assumptions!$B$6) -> 510.75 | J109: =I109*Assumptions!$B$5 -> 648.6525 | K109: =INDEX(Categories!$E$2:$E$31,MATCH($C109,Categories!$A$2:$A$31,0)) -> 150 | L109: =J109*INDEX(Categories!$F$2:$F$31,MATCH($C109,Categories!$A$2:$A$31,0)) -> 16.216313 | M109: =J109*INDEX(Origins!$B$2:$B$4,MATCH($Y109,Origins!$A$2:$A$4,0)) -> 97.297875 | N109: =IF($C109="Alloy wheels",J109*Origins!$B$7*INDEX(Origins!$C$2:$C$4,MATCH($Y109,Origins!$A$2:$A$4,0)),0) -> 129.7305 | O109: =J109*Assumptions!$B$7+Assumptions!$B$8/Assumptions!$B$9 -> 27.246932 | P109: =J109+K109+L109+M109+N109+O109 -> 1069.1441 | Q109: =H109*Assumptions!$B$5+K109+L109+M109+N109+O109 -> 1285.3616 | R109: =INDEX(Categories!$B$2:$B$31,MATCH($C109,Categories!$A$2:$A$31,0)) -> 2 | S109: =INDEX(Categories!$C$2:$C$31,MATCH($C109,Categories!$A$2:$A$31,0)) -> 0 | T109: =R109*Assumptions!$B$10+S109*Assumptions!$B$11 -> 400 | U109: =INDEX(Categories!$D$2:$D$31,MATCH($C109,Categories!$A$2:$A$31,0)) -> 0 | V109: =T109+U109 -> 400 | W109: =Q109+V109 -> 1685.3616 | Y109: =IF($X109="",INDEX(Categories!$G$2:$G$31,MATCH($C109,Categories!$A$2:$A$31,0)),$X109) -> Taiwan | Z109: 864.87 | AA109: https://chelseatruckcompany.com/products/land-rover-defender-satin-black-mondial-retro-alloy-wheel-set-of-4
A110: Alloy wheels | B110: wheels | C110: Alloy wheels | D110: Land Rover Defender (1991-2016) RS-Forged Alloy Wheels - Rostyle Inspired (1970DEF902RB1) | E110: 1970DEF902RB1 | F110: No | G110: Land Rover Defender 110 (1991–2016); Land Rover Defender 90 (1991–2016) | H110: 567 | I110: =H110*(1-Assumptions!$B$6) -> 425.25 | J110: =I110*Assumptions!$B$5 -> 540.0675 | K110: =INDEX(Categories!$E$2:$E$31,MATCH($C110,Categories!$A$2:$A$31,0)) -> 150 | L110: =J110*INDEX(Categories!$F$2:$F$31,MATCH($C110,Categories!$A$2:$A$31,0)) -> 13.501687 | M110: =J110*INDEX(Origins!$B$2:$B$4,MATCH($Y110,Origins!$A$2:$A$4,0)) -> 81.010125 | N110: =IF($C110="Alloy wheels",J110*Origins!$B$7*INDEX(Origins!$C$2:$C$4,MATCH($Y110,Origins!$A$2:$A$4,0)),0) -> 108.0135 | O110: =J110*Assumptions!$B$7+Assumptions!$B$8/Assumptions!$B$9 -> 26.870794 | P110: =J110+K110+L110+M110+N110+O110 -> 919.46361 | Q110: =H110*Assumptions!$B$5+K110+L110+M110+N110+O110 -> 1099.4861 | R110: =INDEX(Categories!$B$2:$B$31,MATCH($C110,Categories!$A$2:$A$31,0)) -> 2 | S110: =INDEX(Categories!$C$2:$C$31,MATCH($C110,Categories!$A$2:$A$31,0)) -> 0 | T110: =R110*Assumptions!$B$10+S110*Assumptions!$B$11 -> 400 | U110: =INDEX(Categories!$D$2:$D$31,MATCH($C110,Categories!$A$2:$A$31,0)) -> 0 | V110: =T110+U110 -> 400 | W110: =Q110+V110 -> 1499.4861 | Y110: =IF($X110="",INDEX(Categories!$G$2:$G$31,MATCH($C110,Categories!$A$2:$A$31,0)),$X110) -> Taiwan | Z110: 720.09 | AA110: https://chelseatruckcompany.com/products/land-rover-defender-1991-2016-rostyle-inspired-rs-forged-alloy-wheels-sale
A111: Alloy wheels | B111: wheels | C111: Alloy wheels | D111: Land Rover Defender (1991-2016) RS-Forged Alloy Wheels - Rostyle Inspired (WACRF8151M1R-2) | E111: WACRF8151M1R-2 | F111: No | G111: Land Rover Defender 110 (1991–2016); Land Rover Defender 90 (1991–2016) | H111: 454 | I111: =H111*(1-Assumptions!$B$6) -> 340.5 | J111: =I111*Assumptions!$B$5 -> 432.435 | K111: =INDEX(Categories!$E$2:$E$31,MATCH($C111,Categories!$A$2:$A$31,0)) -> 150 | L111: =J111*INDEX(Categories!$F$2:$F$31,MATCH($C111,Categories!$A$2:$A$31,0)) -> 10.810875 | M111: =J111*INDEX(Origins!$B$2:$B$4,MATCH($Y111,Origins!$A$2:$A$4,0)) -> 64.86525 | N111: =IF($C111="Alloy wheels",J111*Origins!$B$7*INDEX(Origins!$C$2:$C$4,MATCH($Y111,Origins!$A$2:$A$4,0)),0) -> 86.487 | O111: =J111*Assumptions!$B$7+Assumptions!$B$8/Assumptions!$B$9 -> 26.497955 | P111: =J111+K111+L111+M111+N111+O111 -> 771.09608 | Q111: =H111*Assumptions!$B$5+K111+L111+M111+N111+O111 -> 915.24108 | R111: =INDEX(Categories!$B$2:$B$31,MATCH($C111,Categories!$A$2:$A$31,0)) -> 2 | S111: =INDEX(Categories!$C$2:$C$31,MATCH($C111,Categories!$A$2:$A$31,0)) -> 0 | T111: =R111*Assumptions!$B$10+S111*Assumptions!$B$11 -> 400 | U111: =INDEX(Categories!$D$2:$D$31,MATCH($C111,Categories!$A$2:$A$31,0)) -> 0 | V111: =T111+U111 -> 400 | W111: =Q111+V111 -> 1315.2411 | Y111: =IF($X111="",INDEX(Categories!$G$2:$G$31,MATCH($C111,Categories!$A$2:$A$31,0)),$X111) -> Taiwan | Z111: 576.58 | AA111: https://chelseatruckcompany.com/products/land-rover-defender-1991-2016-rostyle-inspired-matt-silver-rs-forged-alloy-wheels
A112: Alloy wheels | B112: wheels | C112: Alloy wheels | D112: Land Rover Defender (1991-2016) Steel Wheels - 1947 Heritage | E112: WACDF9-51M1S | F112: No | G112: Land Rover Defender 110 (1991–2016); Land Rover Defender 90 (1991–2016) | H112: 341 | I112: =H112*(1-Assumptions!$B$6) -> 255.75 | J112: =I112*Assumptions!$B$5 -> 324.8025 | K112: =INDEX(Categories!$E$2:$E$31,MATCH($C112,Categories!$A$2:$A$31,0)) -> 150 | L112: =J112*INDEX(Categories!$F$2:$F$31,MATCH($C112,Categories!$A$2:$A$31,0)) -> 8.1200625 | M112: =J112*INDEX(Origins!$B$2:$B$4,MATCH($Y112,Origins!$A$2:$A$4,0)) -> 48.720375 | N112: =IF($C112="Alloy wheels",J112*Origins!$B$7*INDEX(Origins!$C$2:$C$4,MATCH($Y112,Origins!$A$2:$A$4,0)),0) -> 64.9605 | O112: =J112*Assumptions!$B$7+Assumptions!$B$8/Assumptions!$B$9 -> 26.125116 | P112: =J112+K112+L112+M112+N112+O112 -> 622.72855 | Q112: =H112*Assumptions!$B$5+K112+L112+M112+N112+O112 -> 730.99605 | R112: =INDEX(Categories!$B$2:$B$31,MATCH($C112,Categories!$A$2:$A$31,0)) -> 2 | S112: =INDEX(Categories!$C$2:$C$31,MATCH($C112,Categories!$A$2:$A$31,0)) -> 0 | T112: =R112*Assumptions!$B$10+S112*Assumptions!$B$11 -> 400 | U112: =INDEX(Categories!$D$2:$D$31,MATCH($C112,Categories!$A$2:$A$31,0)) -> 0 | V112: =T112+U112 -> 400 | W112: =Q112+V112 -> 1130.9961 | Y112: =IF($X112="",INDEX(Categories!$G$2:$G$31,MATCH($C112,Categories!$A$2:$A$31,0)),$X112) -> Taiwan | Z112: 433.07 | AA112: https://chelseatruckcompany.com/products/land-rover-defender-1947-heritage-steel-wheels
... A141: Alloy wheels | B141: wheels | C141: Alloy wheels | D141: Land Rover Defender (2020 Onwards) RS-Forged Alloy Wheels - Hammerhead | E141: WAKHF8357S1R | F141: No | G141: Land Rover Defender 110 (2020–present); Land Rover Defender 130 (2020–present); Land Rover Defender 90 (2020–present) | H141: 567 | I141: =H141*(1-Assumptions!$B$6) -> 425.25 | J141: =I141*Assumptions!$B$5 -> 540.0675 | K141: =INDEX(Categories!$E$2:$E$31,MATCH($C141,Categories!$A$2:$A$31,0)) -> 150 | L141: =J141*INDEX(Categories!$F$2:$F$31,MATCH($C141,Categories!$A$2:$A$31,0)) -> 13.501687 | M141: =J141*INDEX(Origins!$B$2:$B$4,MATCH($Y141,Origins!$A$2:$A$4,0)) -> 81.010125 | N141: =IF($C141="Alloy wheels",J141*Origins!$B$7*INDEX(Origins!$C$2:$C$4,MATCH($Y141,Origins!$A$2:$A$4,0)),0) -> 108.0135 | O141: =J141*Assumptions!$B$7+Assumptions!$B$8/Assumptions!$B$9 -> 26.870794 | P141: =J141+K141+L141+M141+N141+O141 -> 919.46361 | Q141: =H141*Assumptions!$B$5+K141+L141+M141+N141+O141 -> 1099.4861 | R141: =INDEX(Categories!$B$2:$B$31,MATCH($C141,Categories!$A$2:$A$31,0)) -> 2 | S141: =INDEX(Categories!$C$2:$C$31,MATCH($C141,Categories!$A$2:$A$31,0)) -> 0 | T141: =R141*Assumptions!$B$10+S141*Assumptions!$B$11 -> 400 | U141: =INDEX(Categories!$D$2:$D$31,MATCH($C141,Categories!$A$2:$A$31,0)) -> 0 | V141: =T141+U141 -> 400 | W141: =Q141+V141 -> 1499.4861 | Y141: =IF($X141="",INDEX(Categories!$G$2:$G$31,MATCH($C141,Categories!$A$2:$A$31,0)),$X141) -> Taiwan | Z141: 720.09 | AA141: https://chelseatruckcompany.com/products/land-rover-defender-2020-present-rs-forged-alloy-wheels-hammerhead-defender-alloy-wheels
A142: Alloy wheels | C142: Alloy wheels | D142: Land Rover Defender (2020 Onwards) RS-Forged Alloy Wheels - Mondial Heavy Duty | E142: 1994950SB1 | F142: No | G142: Land Rover Defender 110 (2020–present); Land Rover Defender 130 (2020–present); Land Rover Defender 90 (2020–present) | H142: 341 | I142: =H142*(1-Assumptions!$B$6) -> 255.75 | J142: =I142*Assumptions!$B$5 -> 324.8025 | K142: =INDEX(Categories!$E$2:$E$31,MATCH($C142,Categories!$A$2:$A$31,0)) -> 150 | L142: =J142*INDEX(Categories!$F$2:$F$31,MATCH($C142,Categories!$A$2:$A$31,0)) -> 8.1200625 | M142: =J142*INDEX(Origins!$B$2:$B$4,MATCH($Y142,Origins!$A$2:$A$4,0)) -> 48.720375 | N142: =IF($C142="Alloy wheels",J142*Origins!$B$7*INDEX(Origins!$C$2:$C$4,MATCH($Y142,Origins!$A$2:$A$4,0)),0) -> 64.9605 | O142: =J142*Assumptions!$B$7+Assumptions!$B$8/Assumptions!$B$9 -> 26.125116 | P142: =J142+K142+L142+M142+N142+O142 -> 622.72855 | Q142: =H142*Assumptions!$B$5+K142+L142+M142+N142+O142 -> 730.99605 | R142: =INDEX(Categories!$B$2:$B$31,MATCH($C142,Categories!$A$2:$A$31,0)) -> 2 | S142: =INDEX(Categories!$C$2:$C$31,MATCH($C142,Categories!$A$2:$A$31,0)) -> 0 | T142: =R142*Assumptions!$B$10+S142*Assumptions!$B$11 -> 400 | U142: =INDEX(Categories!$D$2:$D$31,MATCH($C142,Categories!$A$2:$A$31,0)) -> 0 | V142: =T142+U142 -> 400 | W142: =Q142+V142 -> 1130.9961 | Y142: =IF($X142="",INDEX(Categories!$G$2:$G$31,MATCH($C142,Categories!$A$2:$A$31,0)),$X142) -> Taiwan | Z142: 433.07 | AA142: https://chelseatruckcompany.com/products/land-rover-defender-2020-present-mondial-heavy-duty-rs-forged-light-alloy-wheels
A143: Alloy wheels | B143: wheels | C143: Alloy wheels | D143: Land Rover Defender (2020 Onwards) RS-Forged Alloy Wheels - Mondial Retro | E143: WACMF9257H1R | F143: No | G143: Land Rover Defender 110 (2020–present); Land Rover Defender 130 (2020–present); Land Rover Defender 90 (2020–present) | H143: 567 | I143: =H143*(1-Assumptions!$B$6) -> 425.25 | J143: =I143*Assumptions!$B$5 -> 540.0675 | K143: =INDEX(Categories!$E$2:$E$31,MATCH($C143,Categories!$A$2:$A$31,0)) -> 150 | L143: =J143*INDEX(Categories!$F$2:$F$31,MATCH($C143,Categories!$A$2:$A$31,0)) -> 13.501687 | M143: =J143*INDEX(Origins!$B$2:$B$4,MATCH($Y143,Origins!$A$2:$A$4,0)) -> 81.010125 | N143: =IF($C143="Alloy wheels",J143*Origins!$B$7*INDEX(Origins!$C$2:$C$4,MATCH($Y143,Origins!$A$2:$A$4,0)),0) -> 108.0135 | O143: =J143*Assumptions!$B$7+Assumptions!$B$8/Assumptions!$B$9 -> 26.870794 | P143: =J143+K143+L143+M143+N143+O143 -> 919.46361 | Q143: =H143*Assumptions!$B$5+K143+L143+M143+N143+O143 -> 1099.4861 | R143: =INDEX(Categories!$B$2:$B$31,MATCH($C143,Categories!$A$2:$A$31,0)) -> 2 | S143: =INDEX(Categories!$C$2:$C$31,MATCH($C143,Categories!$A$2:$A$31,0)) -> 0 | T143: =R143*Assumptions!$B$10+S143*Assumptions!$B$11 -> 400 | U143: =INDEX(Categories!$D$2:$D$31,MATCH($C143,Categories!$A$2:$A$31,0)) -> 0 | V143: =T143+U143 -> 400 | W143: =Q143+V143 -> 1499.4861 | Y143: =IF($X143="",INDEX(Categories!$G$2:$G$31,MATCH($C143,Categories!$A$2:$A$31,0)),$X143) -> Taiwan | Z143: 720.09 | AA143: https://chelseatruckcompany.com/products/land-rover-defender-2020-present-silver-mondial-retro-rs-forged-light-alloy-wheels
A144: Alloy wheels | B144: wheels | C144: Alloy wheels | D144: Land Rover Defender (2020 Onwards) RS-Forged Alloy Wheels - Mondial Retro Light | E144: MOND900B04 | F144: No | G144: Land Rover Defender 110 (2020–present); Land Rover Defender 130 (2020–present); Land Rover Defender 90 (2020–present) | H144: 511 | I144: =H144*(1-Assumptions!$B$6) -> 383.25 | J144: =I144*Assumptions!$B$5 -> 486.7275 | K144: =INDEX(Categories!$E$2:$E$31,MATCH($C144,Categories!$A$2:$A$31,0)) -> 150 | L144: =J144*INDEX(Categories!$F$2:$F$31,MATCH($C144,Categories!$A$2:$A$31,0)) -> 12.168188 | M144: =J144*INDEX(Origins!$B$2:$B$4,MATCH($Y144,Origins!$A$2:$A$4,0)) -> 73.009125 | N144: =IF($C144="Alloy wheels",J144*Origins!$B$7*INDEX(Origins!$C$2:$C$4,MATCH($Y144,Origins!$A$2:$A$4,0)),0) -> 97.3455 | O144: =J144*Assumptions!$B$7+Assumptions!$B$8/Assumptions!$B$9 -> 26.686024 | P144: =J144+K144+L144+M144+N144+O144 -> 845.93634 | Q144: =H144*Assumptions!$B$5+K144+L144+M144+N144+O144 -> 1008.1788 | R144: =INDEX(Categories!$B$2:$B$31,MATCH($C144,Categories!$A$2:$A$31,0)) -> 2 | S144: =INDEX(Categories!$C$2:$C$31,MATCH($C144,Categories!$A$2:$A$31,0)) -> 0 | T144: =R144*Assumptions!$B$10+S144*Assumptions!$B$11 -> 400 | U144: =INDEX(Categories!$D$2:$D$31,MATCH($C144,Categories!$A$2:$A$31,0)) -> 0 | V144: =T144+U144 -> 400 | W144: =Q144+V144 -> 1408.1788 | Y144: =IF($X144="",INDEX(Categories!$G$2:$G$31,MATCH($C144,Categories!$A$2:$A$31,0)),$X144) -> Taiwan | Z144: 648.97 | AA144: https://chelseatruckcompany.com/products/land-rover-defender-2020-present-satin-black-mondial-retro-rs-forged-light-alloy-wheels
A145: Alloy wheels | B145: wheels | C145: Alloy wheels | D145: Land Rover Defender (2020 Onwards) RS-Forged Alloy Wheels - Type 52 (1) | E145: WAKTF1357S9R-1 | F145: No | G145: Land Rover Defender 110 (2020–present); Land Rover Defender 130 (2020–present); Land Rover Defender 90 (2020–present) | H145: 851 | I145: =H145*(1-Assumptions!$B$6) -> 638.25 | J145: =I145*Assumptions!$B$5 -> 810.5775 | K145: =INDEX(Categories!$E$2:$E$31,MATCH($C145,Categories!$A$2:$A$31,0)) -> 150 | L145: =J145*INDEX(Categories!$F$2:$F$31,MATCH($C145,Categories!$A$2:$A$31,0)) -> 20.264437 | M145: =J145*INDEX(Origins!$B$2:$B$4,MATCH($Y145,Origins!$A$2:$A$4,0)) -> 121.58662 | N145: =IF($C145="Alloy wheels",J145*Origins!$B$7*INDEX(Origins!$C$2:$C$4,MATCH($Y145,Origins!$A$2:$A$4,0)),0) -> 162.1155 | O145: =J145*Assumptions!$B$7+Assumptions!$B$8/Assumptions!$B$9 -> 27.80784 | P145: =J145+K145+L145+M145+N145+O145 -> 1292.3519 | Q145: =H145*Assumptions!$B$5+K145+L145+M145+N145+O145 -> 1562.5444 | R145: =INDEX(Categories!$B$2:$B$31,MATCH($C145,Categories!$A$2:$A$31,0)) -> 2 | S145: =INDEX(Categories!$C$2:$C$31,MATCH($C145,Categories!$A$2:$A$31,0)) -> 0 | T145: =R145*Assumptions!$B$10+S145*Assumptions!$B$11 -> 400 | U145: =INDEX(Categories!$D$2:$D$31,MATCH($C145,Categories!$A$2:$A$31,0)) -> 0 | V145: =T145+U145 -> 400 | W145: =Q145+V145 -> 1962.5444 | Y145: =IF($X145="",INDEX(Categories!$G$2:$G$31,MATCH($C145,Categories!$A$2:$A$31,0)),$X145) -> Taiwan | Z145: 1080.77 | AA145: https://chelseatruckcompany.com/products/land-rover-defender-type-52-rs-forged-alloy-wheels-silver-diamond-cut
A146: Alloy wheels | B146: wheels | C146: Alloy wheels | D146: Land Rover Defender (2020 Onwards) RS-Forged Alloy Wheels - Type 52 (2) | E146: WAKTF1357S9R-2 | F146: No | G146: Land Rover Defender 110 (2020–present); Land Rover Defender 130 (2020–present); Land Rover Defender 90 (2020–present) | H146: 539 | I146: =H146*(1-Assumptions!$B$6) -> 404.25 | J146: =I146*Assumptions!$B$5 -> 513.3975 | K146: =INDEX(Categories!$E$2:$E$31,MATCH($C146,Categories!$A$2:$A$31,0)) -> 150 | L146: =J146*INDEX(Categories!$F$2:$F$31,MATCH($C146,Categories!$A$2:$A$31,0)) -> 12.834938 | M146: =J146*INDEX(Origins!$B$2:$B$4,MATCH($Y146,Origins!$A$2:$A$4,0)) -> 77.009625 | N146: =IF($C146="Alloy wheels",J146*Origins!$B$7*INDEX(Origins!$C$2:$C$4,MATCH($Y146,Origins!$A$2:$A$4,0)),0) -> 102.6795 | O146: =J146*Assumptions!$B$7+Assumptions!$B$8/Assumptions!$B$9 -> 26.778409 | P146: =J146+K146+L146+M146+N146+O146 -> 882.69997 | Q146: =H146*Assumptions!$B$5+K146+L146+M146+N146+O146 -> 1053.8325 | R146: =INDEX(Categories!$B$2:$B$31,MATCH($C146,Categories!$A$2:$A$31,0)) -> 2 | S146: =INDEX(Categories!$C$2:$C$31,MATCH($C146,Categories!$A$2:$A$31,0)) -> 0 | T146: =R146*Assumptions!$B$10+S146*Assumptions!$B$11 -> 400 | U146: =INDEX(Categories!$D$2:$D$31,MATCH($C146,Categories!$A$2:$A$31,0)) -> 0 | V146: =T146+U146 -> 400 | W146: =Q146+V146 -> 1453.8325 | Y146: =IF($X146="",INDEX(Categories!$G$2:$G$31,MATCH($C146,Categories!$A$2:$A$31,0)),$X146) -> Taiwan | Z146: 684.53 | AA146: https://chelseatruckcompany.com/products/land-rover-defender-2020-present-type-52-rs-forged-alloy-wheels
A147: Alloy wheels | B147: wheels | C147: Alloy wheels | D147: Land Rover Defender (2020 Onwards) RS-Forged Alloy Wheels - Type 57 (T57102SB1) | E147: T57102SB1 | F147: No | G147: Land Rover Defender 110 (2020–present); Land Rover Defender 130 (2020–present); Land Rover Defender 90 (2020–present) | H147: 794 | I147: =H147*(1-Assumptions!$B$6) -> 595.5 | J147: =I147*Assumptions!$B$5 -> 756.285 | K147: =INDEX(Categories!$E$2:$E$31,MATCH($C147,Categories!$A$2:$A$31,0)) -> 150 | L147: =J147*INDEX(Categories!$F$2:$F$31,MATCH($C147,Categories!$A$2:$A$31,0)) -> 18.907125 | M147: =J147*INDEX(Origins!$B$2:$B$4,MATCH($Y147,Origins!$A$2:$A$4,0)) -> 113.44275 | N147: =IF($C147="Alloy wheels",J147*Origins!$B$7*INDEX(Origins!$C$2:$C$4,MATCH($Y147,Origins!$A$2:$A$4,0)),0) -> 151.257 | O147: =J147*Assumptions!$B$7+Assumptions!$B$8/Assumptions!$B$9 -> 27.619771 | P147: =J147+K147+L147+M147+N147+O147 -> 1217.5116 | Q147: =H147*Assumptions!$B$5+K147+L147+M147+N147+O147 -> 1469.6066 | R147: =INDEX(Categories!$B$2:$B$31,MATCH($C147,Categories!$A$2:$A$31,0)) -> 2 | S147: =INDEX(Categories!$C$2:$C$31,MATCH($C147,Categories!$A$2:$A$31,0)) -> 0 | T147: =R147*Assumptions!$B$10+S147*Assumptions!$B$11 -> 400 | U147: =INDEX(Categories!$D$2:$D$31,MATCH($C147,Categories!$A$2:$A$31,0)) -> 0 | V147: =T147+U147 -> 400 | W147: =Q147+V147 -> 1869.6066 | Y147: =IF($X147="",INDEX(Categories!$G$2:$G$31,MATCH($C147,Categories!$A$2:$A$31,0)),$X147) -> Taiwan | Z147: 1008.38 | AA147: https://chelseatruckcompany.com/products/land-rover-defender-2020-present-type-57-rs-forged-alloy-wheels-3
A148: Alloy wheels | B148: wheels | C148: Alloy wheels | D148: Land Rover Defender (2020 Onwards) RS-Forged Alloy Wheels - Type 57 (T57103MB2) | E148: T57103MB2 | F148: No | G148: Land Rover Defender 110 (2020–present); Land Rover Defender 130 (2020–present); Land Rover Defender 90 (2020–present) | H148: 992 | I148: =H148*(1-Assumptions!$B$6) -> 744 | J148: =I148*Assumptions!$B$5 -> 944.88 | K148: =INDEX(Categories!$E$2:$E$31,MATCH($C148,Categories!$A$2:$A$31,0)) -> 150 | L148: =J148*INDEX(Categories!$F$2:$F$31,MATCH($C148,Categories!$A$2:$A$31,0)) -> 23.622 | M148: =J148*INDEX(Origins!$B$2:$B$4,MATCH($Y148,Origins!$A$2:$A$4,0)) -> 141.732 | N148: =IF($C148="Alloy wheels",J148*Origins!$B$7*INDEX(Origins!$C$2:$C$4,MATCH($Y148,Origins!$A$2:$A$4,0)),0) -> 188.976 | O148: =J148*Assumptions!$B$7+Assumptions!$B$8/Assumptions!$B$9 -> 28.273064 | P148: =J148+K148+L148+M148+N148+O148 -> 1477.4831 | Q148: =H148*Assumptions!$B$5+K148+L148+M148+N148+O148 -> 1792.4431 | R148: =INDEX(Categories!$B$2:$B$31,MATCH($C148,Categories!$A$2:$A$31,0)) -> 2 | S148: =INDEX(Categories!$C$2:$C$31,MATCH($C148,Categories!$A$2:$A$31,0)) -> 0 | T148: =R148*Assumptions!$B$10+S148*Assumptions!$B$11 -> 400 | U148: =INDEX(Categories!$D$2:$D$31,MATCH($C148,Categories!$A$2:$A$31,0)) -> 0 | V148: =T148+U148 -> 400 | W148: =Q148+V148 -> 2192.4431 | Y148: =IF($X148="",INDEX(Categories!$G$2:$G$31,MATCH($C148,Categories!$A$2:$A$31,0)),$X148) -> Taiwan | Z148: 1259.84 | AA148: https://chelseatruckcompany.com/products/land-rover-defender-2020-present-type-57-dc-rs-forged-alloy-wheels-defender-110
